<?xml version="1.0"?>

<!-- 
  This file contains a sphere of radius=0.06m.
  The sphere is a manipuland for demonstration with allegro hand.
  Note: the sphere rotate only around the z-axis, with fixed x
  and y value compatible with the allegro_hand_right model in
  the repository quasistatic_simulator
  (https://github.com/pangtao22/quasistatic_simulator)
  This version is copied from allegro_3d_sphere_z.sdf, with only
  changes in the base location. This version is used in allegro
  hand manipulation with 4 fingers.
-->

<sdf version="1.7">
  <model name="sphere_r0.06m">

    <joint name="world_sphere_offset" type="fixed">
      <child>sphere_root</child>
      <parent>world</parent>
      <axis>
        <limit>
          <effort>0</effort>
        </limit>
      </axis>
    </joint>

    <link name="sphere_root">
      <!-- <pose relative_to="__model__">-0.081 0.001 0.071 0 0 0</pose> -->
      <pose relative_to="__model__">-0.06 0.0 0.072 0 0 0</pose>
    </link>

    <joint name="sphere_root_joint" type="revolute">
        <child>sphere_link</child>
        <parent>sphere_root</parent>
        <axis>
          <xyz>0 0 1</xyz>
          <limit>
            <effort>0</effort>
          </limit>
          <!-- <dynamics>
            <damping>1.5e-2</damping>
          </dynamics> -->
        </axis>
    </joint>

    <link name="sphere_link">
      <pose relative_to="sphere_root">0 0 0 0 0 0</pose>
      <inertial>
        <mass>1.0</mass>
        <inertia>
          <ixx>0.001</ixx>
          <ixy>0</ixy>
          <ixz>0</ixz>
          <iyy>0.001</iyy>
          <iyz>0</iyz>
          <izz>0.001</izz>
        </inertia>
      </inertial>

      <visual name="visual">
        <geometry>
          <sphere>
            <radius>0.06</radius>
          </sphere>
        </geometry>
        <material>
          <diffuse>0.1 0.5 0.5 0.8</diffuse>
        </material>
      </visual>

      <visual name="visual_2">
        <pose> 0 0 0.06 0 0 0 </pose>
        <geometry>
          <box>
           <size>0.02 0.02 0.002 </size>
          </box>
        </geometry>
        <material>
          <diffuse>0.6 0.2 0.2 0.9</diffuse>
        </material>
      </visual>

      <collision name="collision">
        <geometry>
          <sphere>
            <radius>0.06</radius>
          </sphere>
        </geometry>
        <surface>
          <friction>
            <ode>
              <mu>1.0</mu>
              <mu2>1.0</mu2>
            </ode>
          </friction>
        </surface>
      </collision>
    </link>

  </model>
</sdf>
