<?xml version="1.0"?>
<sdf version="1.7">
  <model name="iiwa7">
    <link name="iiwa_link_0">
      <inertial>
        <pose>-0.013 0 0.07 0 0 0</pose>
        <mass>3.863</mass>
        <inertia>
          <ixx>0.0141</ixx>
          <ixy>0</ixy>
          <ixz>0</ixz>
          <iyy>0.0171</iyy>
          <iyz>0</iyz>
          <izz>0.0178</izz>
        </inertia>
      </inertial>
      <visual name="iiwa_link_0_visual">
        <geometry>
          <mesh>
            <scale>1 1 1</scale>
            <uri>package://drake_manipulation_models/iiwa_description/iiwa7/meshes/collision/link_0.obj</uri>
          </mesh>
        </geometry>
        <material>
          <diffuse>0.4 0.4 0.4 1.0</diffuse>
        </material>
      </visual>
      <gravity>1</gravity>
    </link>
    <link name="iiwa_link_1">
      <pose relative_to="iiwa_link_0"> 0 0 0.15 0 0 0 </pose>
      <inertial>
        <pose>0 -0.0347 0.113 0 0 0</pose>
        <mass>2.7025</mass>
        <inertia>
          <ixx>0.0171</ixx>
          <ixy>0</ixy>
          <ixz>0</ixz>
          <iyy>0.0163</iyy>
          <iyz>0</iyz>
          <izz>0.006</izz>
        </inertia>
      </inertial>
      <visual name="iiwa_link_1_visual">
        <pose> 0 0 0.0075 0 0 0 </pose>
        <geometry>
          <mesh>
            <scale>1 1 1</scale>
            <uri>package://drake_manipulation_models/iiwa_description/iiwa7/meshes/collision/link_1.obj</uri>
          </mesh>
        </geometry>
        <material>
          <diffuse>0.4 0.4 0.4 0.5</diffuse>
        </material>
      </visual>
      <collision name='iiwa_link_1_contact'>
        <pose> 0 0 0.0075 0 0 0 </pose>
        <geometry>
          <mesh>
            <scale>1 1 1</scale>
            <uri>package://drake_manipulation_models/iiwa_description/iiwa7/meshes/collision/link_1.obj</uri>
          </mesh>
        </geometry>
        <surface>
          <friction>
          <ode>
            <mu>0.5</mu>
            <mu2>0.5</mu2>
          </ode>
          </friction>
        </surface>
      </collision>
      <visual name='iiwa_link_1_contact_visual'>
        <pose> 0 0 0.0075 0 0 0 </pose>
        <geometry>
          <mesh>
            <scale>1 1 1</scale>
            <uri>package://drake_manipulation_models/iiwa_description/iiwa7/meshes/collision/link_1.obj</uri>
          </mesh>
        </geometry>
        <material>
          <diffuse>0.8 0.8 0.8 1.0</diffuse>
        </material>
      </visual>
      <gravity>1</gravity>
    </link>
    <joint name="iiwa_joint_1" type="revolute">
      <child>iiwa_link_1</child>
      <parent>iiwa_link_0</parent>
      <axis>
        <xyz expressed_in="__model__">0 0 1</xyz>
        <limit>
          <lower>-2.96706</lower>
          <upper>2.96706</upper>
          <effort>300</effort>
          <velocity>10</velocity>
        </limit>
        <dynamics>
          <damping>0.0</damping>
          <friction>0</friction>
          <spring_reference>0</spring_reference>
          <spring_stiffness>0</spring_stiffness>
        </dynamics>
      </axis>
    </joint>
    <link name="iiwa_link_2">
      <pose relative_to="iiwa_link_1"> 0 0 0.19 1.5707 0 3.1416 </pose>
      <inertial>
        <pose>0.000 0.0668 0.0344 0 0 0</pose>
        <mass>2.7258</mass>
        <inertia>
          <ixx>0.0170</ixx>
          <ixy>0</ixy>
          <ixz>0</ixz>
          <iyy>0.0162</iyy>
          <iyz>0</iyz>
          <izz>0.0061</izz>
        </inertia>
      </inertial>
      <visual name="iiwa_link_2_visual">
        <pose>0 0 0 0 0 0</pose>
        <geometry>
          <mesh>
            <scale>1 1 1</scale>
            <uri>package://drake_manipulation_models/iiwa_description/iiwa7/meshes/collision/link_2.obj</uri>
          </mesh>
        </geometry>
        <material>
          <diffuse>1.0 0.423529411765 0.0392156862745 0.5</diffuse>
        </material>
      </visual>
      <visual name='iiwa_link_2_contact_visual'>
        <pose>0 0 0 0 0 0</pose>
        <geometry>
          <mesh>
            <scale>1 1 1</scale>
            <uri>package://drake_manipulation_models/iiwa_description/iiwa7/meshes/collision/link_2.obj</uri>
          </mesh>
        </geometry>
        <material>
          <diffuse>0.8 0.8 0.8 1.0</diffuse>
        </material>
      </visual>
      <collision name='iiwa_link_2_contact'>
        <pose>0 0 0 0 0 0</pose>
        <geometry>
          <mesh>
            <scale>1 1 1</scale>
            <uri>package://drake_manipulation_models/iiwa_description/iiwa7/meshes/collision/link_2.obj</uri>
          </mesh>
        </geometry>
        <surface>
          <friction>
          <ode>
            <mu>0.5</mu>
            <mu2>0.5</mu2>
          </ode>
          </friction>
        </surface>
      </collision>
      <gravity>1</gravity>
    </link>
    <joint name="iiwa_joint_2" type="revolute">
      <child>iiwa_link_2</child>
      <parent>iiwa_link_1</parent>
      <axis>
        <xyz expressed_in="__model__">-0 1 0</xyz>
        <limit>
          <lower>-2.0944</lower>
          <upper>2.0944</upper>
          <effort>300</effort>
          <velocity>10</velocity>
        </limit>
        <dynamics>
          <damping>0.0</damping>
          <friction>0</friction>
          <spring_reference>0</spring_reference>
          <spring_stiffness>0</spring_stiffness>
        </dynamics>
      </axis>
    </joint>
    <link name="iiwa_link_3">
      <pose relative_to="iiwa_link_2">0 0.21 0 1.5708 0 3.1416</pose>
      <inertial>
        <pose>0 0.0296 0.1265 0 0 0</pose>
        <mass>3.175</mass>
        <inertia>
          <ixx>0.025</ixx>
          <ixy>0</ixy>
          <ixz>0</ixz>
          <iyy>0.0238</iyy>
          <iyz>0</iyz>
          <izz>0.0076</izz>
        </inertia>
      </inertial>
      <visual name="iiwa_link_3_visual">
        <pose>0 0 -0.026 0 0 0</pose>
        <geometry>
          <mesh>
            <scale>1 1 1</scale>
            <uri>package://drake_manipulation_models/iiwa_description/iiwa7/meshes/collision/link_3.obj</uri>
          </mesh>
        </geometry>
        <material>
          <diffuse>0.4 0.4 0.4 0.5</diffuse>
        </material>
      </visual>
      <visual name='iiwa_link_3_contact_visual'>
        <pose>0 0 -0.026 0 0 0</pose>
        <geometry>
          <mesh>
            <scale>1 1 1</scale>
            <uri>package://drake_manipulation_models/iiwa_description/iiwa7/meshes/collision/link_3.obj</uri>
          </mesh>
        </geometry>
        <material>
          <diffuse>0.8 0.8 0.8 1.0</diffuse>
        </material>
      </visual>
      <collision name='iiwa_link_3_contact'>
        <pose>0 0 -0.026 0 0 0</pose>
        <geometry>
          <mesh>
            <scale>1 1 1</scale>
            <uri>package://drake_manipulation_models/iiwa_description/iiwa7/meshes/collision/link_3.obj</uri>
          </mesh>
        </geometry>
        <surface>
          <friction>
          <ode>
            <mu>0.5</mu>
            <mu2>0.5</mu2>
          </ode>
          </friction>
        </surface>
      </collision>
      <gravity>1</gravity>
    </link>
    <joint name="iiwa_joint_3" type="revolute">
      <child>iiwa_link_3</child>
      <parent>iiwa_link_2</parent>
      <axis>
        <xyz expressed_in="__model__">0 0 1</xyz>
        <limit>
          <lower>-2.96706</lower>
          <upper>2.96706</upper>
          <effort>300</effort>
          <velocity>10</velocity>
        </limit>
        <dynamics>
          <damping>0.0</damping>
          <friction>0</friction>
          <spring_reference>0</spring_reference>
          <spring_stiffness>0</spring_stiffness>
        </dynamics>
      </axis>
    </joint>
    <link name="iiwa_link_4">
      <pose relative_to="iiwa_link_3"> 0 0 0.19 1.5708 0 0 </pose>
      <inertial>
        <pose>0 0.067 0.034 0 0 0</pose>
        <mass>2.73</mass>
        <inertia>
          <ixx>0.017</ixx>
          <ixy>0</ixy>
          <ixz>0</ixz>
          <iyy>0.0162</iyy>
          <iyz>0</iyz>
          <izz>0.0061</izz>
        </inertia>
      </inertial>
      <visual name="iiwa_link_4_visual">
        <pose>0 0 0 0 0 0</pose>
        <geometry>
          <mesh>
            <scale>1 1 1</scale>
            <uri>package://drake_manipulation_models/iiwa_description/iiwa7/meshes/collision/link_4.obj</uri>
          </mesh>
        </geometry>
        <material>
          <diffuse>1.0 0.42 0.04 0.5</diffuse>
        </material>
      </visual>
      <visual name='iiwa_link_4_contact_visual'>
        <pose>0 0 0 0 0 0</pose>
        <geometry>
          <mesh>
            <scale>1 1 1</scale>
            <uri>package://drake_manipulation_models/iiwa_description/iiwa7/meshes/collision/link_4.obj</uri>
          </mesh>
        </geometry>
        <material>
          <diffuse>0.8 0.8 0.8 1.0</diffuse>
        </material>
      </visual>
      <collision name='iiwa_link_4_contact'>
        <pose>0 0 0 0 0 0</pose>
        <geometry>
          <mesh>
            <scale>1 1 1</scale>
            <uri>package://drake_manipulation_models/iiwa_description/iiwa7/meshes/collision/link_4.obj</uri>
          </mesh>
        </geometry>
        <surface>
          <friction>
          <ode>
            <mu>0.5</mu>
            <mu2>0.5</mu2>
          </ode>
          </friction>
        </surface>
      </collision>
      <gravity>1</gravity>
    </link>
    <joint name="iiwa_joint_4" type="revolute">
      <child>iiwa_link_4</child>
      <parent>iiwa_link_3</parent>
      <axis>
        <xyz expressed_in="__model__">0 -1 0</xyz>
        <limit>
          <lower>-2.0944</lower>
          <upper>2.0944</upper>
          <effort>300</effort>
          <velocity>10</velocity>
        </limit>
        <dynamics>
          <damping>0.0</damping>
          <friction>0</friction>
          <spring_reference>0</spring_reference>
          <spring_stiffness>0</spring_stiffness>
        </dynamics>
      </axis>
    </joint>
    <link name="iiwa_link_5">
      <pose relative_to="iiwa_link_4"> 0 0.21 0 -1.5707 3.1416 0 </pose>
      <inertial>
        <pose>0.0001 0.021 0.076 0 0 0</pose>
        <mass>1.69</mass>
        <inertia>
          <ixx>0.01</ixx>
          <ixy>0</ixy>
          <ixz>0</ixz>
          <iyy>0.0087</iyy>
          <iyz>0</iyz>
          <izz>0.00449</izz>
        </inertia>
      </inertial>
      <visual name="iiwa_link_5_visual">
        <pose> 0 0 -0.026 0 0 0 </pose>
        <geometry>
          <mesh>
            <scale>1 1 1</scale>
            <uri>package://drake_manipulation_models/iiwa_description/iiwa7/meshes/collision/link_5.obj</uri>
          </mesh>
        </geometry>
        <material>
          <diffuse>0.4 0.4 0.4 0.5</diffuse>
        </material>
      </visual>

      <visual name='iiwa_link_5_contact_visual'>
        <pose> 0 0 -0.026 0 0 0 </pose>
        <geometry>
          <mesh>
            <scale>1 1 1</scale>
            <uri>package://drake_manipulation_models/iiwa_description/iiwa7/meshes/collision/link_5.obj</uri>
          </mesh>
        </geometry>
        <material>
          <diffuse>0.8 0.8 0.8 1.0</diffuse>
        </material>
      </visual>

      <collision name='iiwa_link_5_contact'>
        <pose> 0 0 -0.026 0 0 0 </pose>
        <geometry>
          <mesh>
            <scale>1 1 1</scale>
            <uri>package://drake_manipulation_models/iiwa_description/iiwa7/meshes/collision/link_5.obj</uri>
          </mesh>
        </geometry>
        <surface>
          <friction>
          <ode>
            <mu>0.5</mu>
            <mu2>0.5</mu2>
          </ode>
          </friction>
        </surface>
      </collision>

      <gravity>1</gravity>
    </link>
    <joint name="iiwa_joint_5" type="revolute">
      <child>iiwa_link_5</child>
      <parent>iiwa_link_4</parent>
      <axis>
        <xyz expressed_in="__model__">0 0 1</xyz>
        <limit>
          <lower>-2.96706</lower>
          <upper>2.96706</upper>
          <effort>300</effort>
          <velocity>10</velocity>
        </limit>
        <dynamics>
          <damping>0.0</damping>
          <friction>0</friction>
          <spring_reference>0</spring_reference>
          <spring_stiffness>0</spring_stiffness>
        </dynamics>
      </axis>
    </joint>
    <link name="iiwa_link_6">
      <pose relative_to="iiwa_link_5"> 0 0.06070 0.19 1.5708 0 0 </pose>
      <inertial>
        <pose>0 0.0026 0.0005 0 0 0</pose>
        <mass>1.8</mass>
        <inertia>
          <ixx>0.0051</ixx>
          <ixy>0</ixy>
          <ixz>0</ixz>
          <iyy>0.0049</iyy>
          <iyz>0</iyz>
          <izz>0.0035</izz>
        </inertia>
      </inertial>
      <visual name="iiwa_link_6_visual">
        <pose>0 0 0 0 0 0</pose>
        <geometry>
          <mesh>
            <scale>1 1 1</scale>
            <uri>package://drake_manipulation_models/iiwa_description/iiwa7/meshes/collision/link_6.obj</uri>
          </mesh>
        </geometry>
        <material>
          <diffuse>1.0 0.42 0.04 0.5</diffuse>
        </material>
      </visual>

      <visual name='iiwa_link_6_contact_visual'>
        <pose>0 0 0 0 0 0</pose>
        <geometry>
          <mesh>
            <scale>1 1 1</scale>
            <uri>package://drake_manipulation_models/iiwa_description/iiwa7/meshes/collision/link_6.obj</uri>
          </mesh>
        </geometry>
        <material>
          <diffuse>0.8 0.8 0.8 1.0</diffuse>
        </material>
      </visual>

      <collision name='iiwa_link_6_contact'>
        <pose>0 0 0 0 0 0</pose>
        <geometry>
          <mesh>
            <scale>1 1 1</scale>
            <uri>package://drake_manipulation_models/iiwa_description/iiwa7/meshes/collision/link_6.obj</uri>
          </mesh>
        </geometry>
        <surface>
          <friction>
          <ode>
            <mu>0.5</mu>
            <mu2>0.5</mu2>
          </ode>
          </friction>
        </surface>
      </collision>

      <gravity>1</gravity>
    </link>
    <joint name="iiwa_joint_6" type="revolute">
      <child>iiwa_link_6</child>
      <parent>iiwa_link_5</parent>
      <axis>
        <xyz expressed_in="__model__">-0 1 -0</xyz>
        <limit>
          <lower>-2.0944</lower>
          <upper>2.0944</upper>
          <effort>300</effort>
          <velocity>10</velocity>
        </limit>
        <dynamics>
          <damping>0.0</damping>
          <friction>0</friction>
          <spring_reference>0</spring_reference>
          <spring_stiffness>0</spring_stiffness>
        </dynamics>
      </axis>
    </joint>
    <link name="iiwa_link_7">
      <pose relative_to="iiwa_link_6"> 0 0.081 0.06070 -1.5707 3.1416 0 </pose>
      <inertial>
        <pose>0 0 0.0294 0 0 0</pose>
        <mass>.4</mass>
        <inertia>
          <ixx>0.0004</ixx>
          <ixy>0</ixy>
          <ixz>0</ixz>
          <iyy>0.0004</iyy>
          <iyz>0</iyz>
          <izz>0.0005</izz>
        </inertia>
      </inertial>
      <visual name="iiwa_link_7_visual">
        <geometry>
          <mesh>
            <scale>1 1 1</scale>
            <uri>package://drake_manipulation_models/iiwa_description/iiwa7/meshes/collision/link_7.obj</uri>
          </mesh>
        </geometry>
        <material>
          <diffuse>0.4 0.4 0.4 1.0</diffuse>
        </material>
      </visual>

      <visual name='iiwa_link_7_contact_visual'>
        <pose> 0 0 -0.0005 0 0 0 </pose>
        <geometry>
          <mesh>
            <scale>1 1 1</scale>
            <uri>package://drake_manipulation_models/iiwa_description/iiwa7/meshes/collision/link_7.obj</uri>
          </mesh>
        </geometry>
        <material>
          <diffuse>0.8 0.8 0.8 1.0</diffuse>
        </material>
      </visual>

      <collision name='iiwa_link_7_contact'>
        <pose> 0 0 -0.0005 0 0 0 </pose>
        <geometry>
          <mesh>
            <scale>1 1 1</scale>
            <uri>package://drake_manipulation_models/iiwa_description/iiwa7/meshes/collision/link_7.obj</uri>
          </mesh>
        </geometry>
        <surface>
          <friction>
          <ode>
            <mu>0.5</mu>
            <mu2>0.5</mu2>
          </ode>
          </friction>
        </surface>
      </collision>


      <gravity>1</gravity>
    </link>
    <joint name="iiwa_joint_7" type="revolute">
      <child>iiwa_link_7</child>
      <parent>iiwa_link_6</parent>
      <axis>
        <xyz expressed_in="__model__">0 0 1</xyz>
        <limit>
          <lower>-3.05433</lower>
          <upper>3.05433</upper>
          <effort>300</effort>
          <velocity>10</velocity>
        </limit>
        <dynamics>
          <damping>0.0</damping>
          <friction>0</friction>
          <spring_reference>0</spring_reference>
          <spring_stiffness>0</spring_stiffness>
        </dynamics>
      </axis>
    </joint>
    <static>0</static>
  </model>
</sdf>
