<?xml version="1.0"?>
<sdf version="1.7">
  <model name="pointed_fingertip">

    <!-- Create the virtual world link -->

    <link name="virtual_world">
      <inertial>
        <mass>1.0e-6</mass>
        <inertia>
          <ixx>1.0e-6</ixx>
          <ixy>0</ixy>
          <ixz>0</ixz>
          <iyy>1.0e-6</iyy>
          <iyz>0</iyz>
          <izz>1.0e-6</izz>
        </inertia>
      </inertial>
    </link>

    <!-- Create the fingertip 1/3  -->

    <link name="sphere_tip1">
      <inertial>
        <mass>1.0e-6</mass>
        <inertia>
          <ixx>1.0e-6</ixx>
          <ixy>0</ixy>
          <ixz>0</ixz>
          <iyy>1.0e-6</iyy>
          <iyz>0</iyz>
          <izz>1.0e-6</izz>
        </inertia>
      </inertial>

      <visual name="visual">
        <geometry>
          <sphere>
            <radius>0.02</radius>
          </sphere>
        </geometry>
        <material>
          <diffuse>0.1 0.5 0.5 0.8</diffuse>
        </material>
      </visual>

      <collision name="collision">
        <geometry>
          <sphere>
            <radius>0.02</radius>
          </sphere>
        </geometry>
        <surface>
          <friction>
            <ode>
              <mu>1.0</mu>
              <mu2>1.0</mu2>
            </ode>
          </friction>
        </surface>
      </collision>
    </link>

    <link name="ghost_body_x1">
      <inertial>
        <mass>1.0e-6</mass>
        <inertia>
          <ixx>1.0e-6</ixx>
          <ixy>0</ixy>
          <ixz>0</ixz>
          <iyy>1.0e-6</iyy>
          <iyz>0</iyz>
          <izz>1.0e-6</izz>
        </inertia>
      </inertial>
    </link>

    <link name="ghost_body_y1">
      <inertial>
        <mass>1.0e-6</mass>
        <inertia>
          <ixx>1.0e-6</ixx>
          <ixy>0</ixy>
          <ixz>0</ixz>
          <iyy>1.0e-6</iyy>
          <iyz>0</iyz>
          <izz>1.0e-6</izz>
        </inertia>
      </inertial>
    </link>

    <joint name="x_slider1" type="prismatic">
      <parent>virtual_world</parent>
      <child>ghost_body_x1</child>
      <axis>
        <xyz>1 0 0</xyz>
      </axis>
    </joint>

    <joint name="y_slider1" type="prismatic">
      <parent>virtual_world</parent>
      <child>ghost_body_y1</child>
      <axis>
        <xyz>0 1 0</xyz>
      </axis>
    </joint>

    <joint name="z_slider1" type="prismatic">
      <parent>virtual_world</parent>
      <child>sphere_tip1</child>
      <axis>
        <xyz>0 0 1</xyz>
      </axis>
    </joint>

    <!-- Create the fingertip 2/3 -->

    <link name="sphere_tip2">
      <inertial>
        <mass>1.0e-6</mass>
        <inertia>
          <ixx>1.0e-6</ixx>
          <ixy>0</ixy>
          <ixz>0</ixz>
          <iyy>1.0e-6</iyy>
          <iyz>0</iyz>
          <izz>1.0e-6</izz>
        </inertia>
      </inertial>

      <visual name="visual">
        <geometry>
          <sphere>
            <radius>0.02</radius>
          </sphere>
        </geometry>
        <material>
          <diffuse>0.1 0.5 0.5 0.8</diffuse>
        </material>
      </visual>

      <collision name="collision">
        <geometry>
          <sphere>
            <radius>0.02</radius>
          </sphere>
        </geometry>
        <surface>
          <friction>
            <ode>
              <mu>1.0</mu>
              <mu2>1.0</mu2>
            </ode>
          </friction>
        </surface>
      </collision>
    </link>

    <link name="ghost_body_x2">
      <inertial>
        <mass>1.0e-6</mass>
        <inertia>
          <ixx>1.0e-6</ixx>
          <ixy>0</ixy>
          <ixz>0</ixz>
          <iyy>1.0e-6</iyy>
          <iyz>0</iyz>
          <izz>1.0e-6</izz>
        </inertia>
      </inertial>
    </link>

    <link name="ghost_body_y2">
      <inertial>
        <mass>1.0e-6</mass>
        <inertia>
          <ixx>1.0e-6</ixx>
          <ixy>0</ixy>
          <ixz>0</ixz>
          <iyy>1.0e-6</iyy>
          <iyz>0</iyz>
          <izz>1.0e-6</izz>
        </inertia>
      </inertial>
    </link>

    <joint name="x_slider2" type="prismatic">
      <parent>virtual_world</parent>
      <child>ghost_body_x2</child>
      <axis>
        <xyz>1 0 0</xyz>
      </axis>
    </joint>

    <joint name="y_slider2" type="prismatic">
      <parent>virtual_world</parent>
      <child>ghost_body_y2</child>
      <axis>
        <xyz>0 1 0</xyz>
      </axis>
    </joint>

    <joint name="z_slider2" type="prismatic">
      <parent>virtual_world</parent>
      <child>sphere_tip2</child>
      <axis>
        <xyz>0 0 1</xyz>
      </axis>
    </joint>

    <!-- Create the fingertip 3/3 -->

    <link name="sphere_tip3">
      <inertial>
        <mass>1.0e-6</mass>
        <inertia>
          <ixx>1.0e-6</ixx>
          <ixy>0</ixy>
          <ixz>0</ixz>
          <iyy>1.0e-6</iyy>
          <iyz>0</iyz>
          <izz>1.0e-6</izz>
        </inertia>
      </inertial>

      <visual name="visual">
        <geometry>
          <sphere>
            <radius>0.02</radius>
          </sphere>
        </geometry>
        <material>
          <diffuse>0.1 0.5 0.5 0.8</diffuse>
        </material>
      </visual>

      <collision name="collision">
        <geometry>
          <sphere>
            <radius>0.02</radius>
          </sphere>
        </geometry>
        <surface>
          <friction>
            <ode>
              <mu>1.0</mu>
              <mu2>1.0</mu2>
            </ode>
          </friction>
        </surface>
      </collision>
    </link>

    <link name="ghost_body_x3">
      <inertial>
        <mass>1.0e-6</mass>
        <inertia>
          <ixx>1.0e-6</ixx>
          <ixy>0</ixy>
          <ixz>0</ixz>
          <iyy>1.0e-6</iyy>
          <iyz>0</iyz>
          <izz>1.0e-6</izz>
        </inertia>
      </inertial>
    </link>

    <link name="ghost_body_y3">
      <inertial>
        <mass>1.0e-6</mass>
        <inertia>
          <ixx>1.0e-6</ixx>
          <ixy>0</ixy>
          <ixz>0</ixz>
          <iyy>1.0e-6</iyy>
          <iyz>0</iyz>
          <izz>1.0e-6</izz>
        </inertia>
      </inertial>
    </link>

    <joint name="x_slider3" type="prismatic">
      <parent>virtual_world</parent>
      <child>ghost_body_x3</child>
      <axis>
        <xyz>1 0 0</xyz>
      </axis>
    </joint>

    <joint name="y_slider3" type="prismatic">
      <parent>virtual_world</parent>
      <child>ghost_body_y3</child>
      <axis>
        <xyz>0 1 0</xyz>
      </axis>
    </joint>

    <joint name="z_slider3" type="prismatic">
      <parent>virtual_world</parent>
      <child>sphere_tip3</child>
      <axis>
        <xyz>0 0 1</xyz>
      </axis>
    </joint>

  </model>
</sdf>
